<?xml version="1.0"?>
<robot name="manipulator_robot3" xmlns:xacro="http://www.ros.org/wiki/xacro">

    <!-- Define materials for visualization -->
    <material name="blue">
        <color rgba="0.2 0.2 1 0.7"/>
    </material>
    <material name="black">
        <color rgba="0 0 0 0.95"/>
    </material>
    <material name="red">
        <color rgba="1 0 0 0.95"/>
    </material>
    <material name="silver">
        <color rgba="0.9 0.9 0.98 1.0"/>
    </material>

    <!-- Link 'world' for reference -->
    <link name="world"/>

    <!-- base_link is fixed to the world -->
    <joint name="world_to_base_link" type="fixed">
        <parent link="world"/>
        <child link="base_link"/>
        <origin xyz="0 0 0" rpy="0 0 0"/>
    </joint>

    <!-- base_link: cylinder with diameter 0.4 and height 0.1 -->
    <link name="base_link">
        <inertial>
            <origin xyz="0 0 0.05" rpy="0 0 0"/>
            <mass value="1.0"/>
            <inertia 
                ixx="0.0108333" 
                ixy="0.0" 
                ixz="0.0" 
                iyy="0.0108333" 
                iyz="0.0" 
                izz="0.02" />
        </inertial>

        <visual>
            <origin xyz="0 0 0.05" rpy="0 0 0"/>
            <geometry>
                <cylinder length="0.1" radius="0.2"/>
            </geometry>
            <material name="silver"/>
        </visual>

        <collision>
            <origin xyz="0 0 0.05" rpy="0 0 0"/>
            <geometry>
                <cylinder length="0.1" radius="0.2"/>
            </geometry>
        </collision>
    </link>

    <!-- Joint between base_link and link1 -->
    <joint name="base_link_to_link1" type="revolute">
        <parent link="base_link"/>
        <child link="link1"/>
        <origin xyz="0 0 0.1" rpy="0 0 0"/>
        <axis xyz="0 0 1"/>
        <limit lower="${-pi}" upper="${pi}" effort="10" velocity="1.0"/>
    </joint>

    <!-- link1: vertical cylinder with height 0.4 -->
    <link name="link1">
        <inertial>
            <origin xyz="0 0 0.2" rpy="0 0 0"/>
            <mass value="0.5"/>
            <inertia 
                ixx="0.02" 
                ixy="0.0" 
                ixz="0.0" 
                iyy="0.02" 
                iyz="0.0" 
                izz="0.005"/>
        </inertial>
        <visual>
            <origin xyz="0 0 0.2" rpy="0 0 0"/>
            <geometry>
                <cylinder length="0.4" radius="0.08"/>
            </geometry>
            <material name="silver"/>
        </visual>
        <collision>
            <origin xyz="0 0 0.2" rpy="0 0 0"/>
            <geometry>
                <!-- Reduced length in collision geometry to avoid self-collision -->
                <cylinder length="0.3" radius="0.08"/>
            </geometry>
        </collision>
        <!-- Sphere on top for visualization -->
        <visual>
            <origin xyz="0 0 0.4" rpy="0 0 0"/>
            <geometry>
                <sphere radius="0.05"/>
            </geometry>
            <material name="silver"/>
        </visual>
    </link>

    <!-- Joint between link1 and link2 -->
    <joint name="link1_to_link2" type="revolute">
        <parent link="link1"/>
        <child link="link2"/>
        <origin xyz="0 0 0.4" rpy="0 0 0"/>
        <axis xyz="0 1 0"/>
        <limit lower="${-pi/2}" upper="${pi/2}" effort="10" velocity="1.0"/>
    </joint>

    <!-- link2: thinner cylinder -->
    <link name="link2">
        <inertial>
            <origin xyz="0 0 0.2" rpy="0 0 0"/>
            <mass value="0.5"/>
            <inertia 
                ixx="0.02" 
                ixy="0.0" 
                ixz="0.0" 
                iyy="0.02" 
                iyz="0.0" 
                izz="0.005"/>
        </inertial>
        <visual>
            <origin xyz="0 0 0.2" rpy="0 0 0"/>
            <geometry>
                <cylinder length="0.4" radius="0.02"/>
            </geometry>
            <material name="silver"/>
        </visual>
        <collision>
            <origin xyz="0 0 0.2" rpy="0 0 0"/>
            <geometry>
                <cylinder length="0.4" radius="0.02"/>
            </geometry>
        </collision>
    </link>

    <!-- ======================== NEW LINK AND JOINT BELOW ======================= -->

    <!-- link3: an additional link for the 3rd DOF -->
    <link name="link3">
        <inertial>
            <origin xyz="0 0 0.15" rpy="0 0 0"/>
            <mass value="0.5"/>
            <inertia
                ixx="0.02"
                ixy="0.0"
                ixz="0.0"
                iyy="0.02"
                iyz="0.0"
                izz="0.005"/>
        </inertial>
        <visual>
            <origin xyz="0 0 0.15" rpy="0 0 0"/>
            <geometry>
                <cylinder length="0.3" radius="0.02"/>
            </geometry>
            <material name="silver"/>
        </visual>
        <collision>
            <origin xyz="0 0 0.15" rpy="0 0 0"/>
            <geometry>
                <cylinder length="0.3" radius="0.02"/>
            </geometry>
        </collision>
                <!-- Sphere on top for visualization -->
        <visual>
            <origin xyz="0 0 0" rpy="0 0 0"/>
            <geometry>
                <sphere radius="0.03"/>
            </geometry>
            <material name="silver"/>
        </visual>
    </link>

    <!-- 3rd revolute joint between link2 and link3 -->
    <joint name="link2_to_link3" type="revolute">
        <parent link="link2"/>
        <child link="link3"/>
        <origin xyz="0 0 0.4" rpy="0 0 0"/>
        <axis xyz="0 1 0"/>
        <limit lower="${-pi/2}" upper="${pi/2}" effort="10" velocity="1.0"/>
    </joint>

    <!-- ==================== END OF NEW LINK/JOINT SECTION ===================== -->

    <!-- The end_effector remains the same, but now it's fixed to link3 instead of link2 -->
    <link name="end_effector">
        <visual>
            <geometry>
                <sphere radius="0.03"/>
            </geometry>
            <material name="red"/>
        </visual>
    </link>

    <joint name="link3_to_end_effector" type="fixed">
        <parent link="link3"/>
        <child link="end_effector"/>
        <origin xyz="0 0 0.3" rpy="0 0 0"/>
    </joint>

</robot>
